Workbook

Sheet Dashboard
B2: JOB HUNT DASHBOARD
B3: ="Live view | Today: "&TEXT(TODAY(),"dd-mmm-yyyy") -> Live view | Today: 07-Oct-2026
B5: Total Jobs | E5: Applied | H5: Interviews | K5: Offers
B6: =COUNTA(Jobs!$D$4:$D$503) -> 5 | E6: =COUNT(Jobs!$M$4:$M$503) -> 3 | H6: =COUNTIF(Jobs!$L$4:$L$503,"Interview") -> 1 | K6: =COUNTIF(Jobs!$L$4:$L$503,"Offer")+COUNTIF(Jobs!$L$4:$L$503,"Accepted") -> 0
B9: OVERDUE | E9: Due Soon | H9: Follow-ups Due | K9: Response Rate
B10: =COUNTIF(Jobs!$R$4:$R$503,"OVERDUE") -> 1 | E10: =COUNTIF(Jobs!$R$4:$R$503,"DUE SOON") -> 1 | H10: =COUNTIF(Jobs!$R$4:$R$503,"FOLLOW-UP DUE") -> 1 | K10: =IFERROR((COUNTIF(Jobs!$L$4:$L$503,"Interview")+COUNTIF(Jobs!$L$4:$L$503,"Offer")+COUNTIF(Jobs!$L$4:$L$503,"Accepted"))/COUNT(Jobs!$M$4:$M$503),0) -> 0.33333333
B12: Response Rate = (Interview + Offer + Accepted) / Applied. Cards read the Jobs sheet live.
B14: Pipeline (jobs by status)
B15: Status | C15: Jobs | D15: Share
B16: =Settings!B11 -> Wishlist | C16: =COUNTIF(Jobs!$L$4:$L$503,B16) -> 0 | D16: =IF($C$25=0,0,C16/$C$25) -> 0
B17: =Settings!B12 -> To Apply | C17: =COUNTIF(Jobs!$L$4:$L$503,B17) -> 2 | D17: =IF($C$25=0,0,C17/$C$25) -> 0.4
B18: =Settings!B13 -> Applied | C18: =COUNTIF(Jobs!$L$4:$L$503,B18) -> 1 | D18: =IF($C$25=0,0,C18/$C$25) -> 0.2
B19: =Settings!B14 -> Interview | C19: =COUNTIF(Jobs!$L$4:$L$503,B19) -> 1 | D19: =IF($C$25=0,0,C19/$C$25) -> 0.2
B20: =Settings!B15 -> Offer | C20: =COUNTIF(Jobs!$L$4:$L$503,B20) -> 0 | D20: =IF($C$25=0,0,C20/$C$25) -> 0
B21: =Settings!B16 -> Accepted | C21: =COUNTIF(Jobs!$L$4:$L$503,B21) -> 0 | D21: =IF($C$25=0,0,C21/$C$25) -> 0
B22: =Settings!B17 -> Rejected | C22: =COUNTIF(Jobs!$L$4:$L$503,B22) -> 1 | D22: =IF($C$25=0,0,C22/$C$25) -> 0.2
B23: =Settings!B18 -> Withdrawn | C23: =COUNTIF(Jobs!$L$4:$L$503,B23) -> 0 | D23: =IF($C$25=0,0,C23/$C$25) -> 0
B24: =Settings!B19 -> Ghosted | C24: =COUNTIF(Jobs!$L$4:$L$503,B24) -> 0 | D24: =IF($C$25=0,0,C24/$C$25) -> 0
B25: Total | C25: =SUM(C16:C24) -> 5 | D25: =IF(C25=0,0,SUM(D16:D24)) -> 1
B28: Needs Attention (overdue, due soon, follow-up due)
B29: # | C29: ID | D29: Company | E29: Job Title | G29: Status | H29: Alert | I29: Days
B30: 1 | C30: =IFERROR(INDEX(Jobs!$A$4:$A$503,MATCH($B30,Jobs!$W$4:$W$503,0)),"") -> JOB-001 | D30: =IFERROR(INDEX(Jobs!$D$4:$D$503,MATCH($B30,Jobs!$W$4:$W$503,0)),"") -> Acme Corp | E30: =IFERROR(INDEX(Jobs!$E$4:$E$503,MATCH($B30,Jobs!$W$4:$W$503,0)),"") -> Data Analyst | G30: =IFERROR(INDEX(Jobs!$L$4:$L$503,MATCH($B30,Jobs!$W$4:$W$503,0)),"") -> To Apply | H30: =IFERROR(INDEX(Jobs!$R$4:$R$503,MATCH($B30,Jobs!$W$4:$W$503,0)),"") -> DUE SOON | I30: =IFERROR(INDEX(Jobs!$Q$4:$Q$503,MATCH($B30,Jobs!$W$4:$W$503,0)),"") -> 2
B31: 2 | C31: =IFERROR(INDEX(Jobs!$A$4:$A$503,MATCH($B31,Jobs!$W$4:$W$503,0)),"") -> JOB-002 | D31: =IFERROR(INDEX(Jobs!$D$4:$D$503,MATCH($B31,Jobs!$W$4:$W$503,0)),"") -> Globex | E31: =IFERROR(INDEX(Jobs!$E$4:$E$503,MATCH($B31,Jobs!$W$4:$W$503,0)),"") -> Backend Developer | G31: =IFERROR(INDEX(Jobs!$L$4:$L$503,MATCH($B31,Jobs!$W$4:$W$503,0)),"") -> To Apply | H31: =IFERROR(INDEX(Jobs!$R$4:$R$503,MATCH($B31,Jobs!$W$4:$W$503,0)),"") -> OVERDUE | I31: =IFERROR(INDEX(Jobs!$Q$4:$Q$503,MATCH($B31,Jobs!$W$4:$W$503,0)),"") -> -2
B32: 3 | C32: =IFERROR(INDEX(Jobs!$A$4:$A$503,MATCH($B32,Jobs!$W$4:$W$503,0)),"") -> JOB-003 | D32: =IFERROR(INDEX(Jobs!$D$4:$D$503,MATCH($B32,Jobs!$W$4:$W$503,0)),"") -> Initech | E32: =IFERROR(INDEX(Jobs!$E$4:$E$503,MATCH($B32,Jobs!$W$4:$W$503,0)),"") -> Python Developer | G32: =IFERROR(INDEX(Jobs!$L$4:$L$503,MATCH($B32,Jobs!$W$4:$W$503,0)),"") -> Applied | H32: =IFERROR(INDEX(Jobs!$R$4:$R$503,MATCH($B32,Jobs!$W$4:$W$503,0)),"") -> FOLLOW-UP DUE | I32: =IFERROR(INDEX(Jobs!$Q$4:$Q$503,MATCH($B32,Jobs!$W$4:$W$503,0)),"") -> -2
B33: 4 | C33: =IFERROR(INDEX(Jobs!$A$4:$A$503,MATCH($B33,Jobs!$W$4:$W$503,0)),"") | D33: =IFERROR(INDEX(Jobs!$D$4:$D$503,MATCH($B33,Jobs!$W$4:$W$503,0)),"") | E33: =IFERROR(INDEX(Jobs!$E$4:$E$503,MATCH($B33,Jobs!$W$4:$W$503,0)),"") | G33: =IFERROR(INDEX(Jobs!$L$4:$L$503,MATCH($B33,Jobs!$W$4:$W$503,0)),"") | H33: =IFERROR(INDEX(Jobs!$R$4:$R$503,MATCH($B33,Jobs!$W$4:$W$503,0)),"") | I33: =IFERROR(INDEX(Jobs!$Q$4:$Q$503,MATCH($B33,Jobs!$W$4:$W$503,0)),"")
B34: 5 | C34: =IFERROR(INDEX(Jobs!$A$4:$A$503,MATCH($B34,Jobs!$W$4:$W$503,0)),"") | D34: =IFERROR(INDEX(Jobs!$D$4:$D$503,MATCH($B34,Jobs!$W$4:$W$503,0)),"") | E34: =IFERROR(INDEX(Jobs!$E$4:$E$503,MATCH($B34,Jobs!$W$4:$W$503,0)),"") | G34: =IFERROR(INDEX(Jobs!$L$4:$L$503,MATCH($B34,Jobs!$W$4:$W$503,0)),"") | H34: =IFERROR(INDEX(Jobs!$R$4:$R$503,MATCH($B34,Jobs!$W$4:$W$503,0)),"") | I34: =IFERROR(INDEX(Jobs!$Q$4:$Q$503,MATCH($B34,Jobs!$W$4:$W$503,0)),"")
B35: 6 | C35: =IFERROR(INDEX(Jobs!$A$4:$A$503,MATCH($B35,Jobs!$W$4:$W$503,0)),"") | D35: =IFERROR(INDEX(Jobs!$D$4:$D$503,MATCH($B35,Jobs!$W$4:$W$503,0)),"") | E35: =IFERROR(INDEX(Jobs!$E$4:$E$503,MATCH($B35,Jobs!$W$4:$W$503,0)),"") | G35: =IFERROR(INDEX(Jobs!$L$4:$L$503,MATCH($B35,Jobs!$W$4:$W$503,0)),"") | H35: =IFERROR(INDEX(Jobs!$R$4:$R$503,MATCH($B35,Jobs!$W$4:$W$503,0)),"") | I35: =IFERROR(INDEX(Jobs!$Q$4:$Q$503,MATCH($B35,Jobs!$W$4:$W$503,0)),"")
B36: 7 | C36: =IFERROR(INDEX(Jobs!$A$4:$A$503,MATCH($B36,Jobs!$W$4:$W$503,0)),"") | D36: =IFERROR(INDEX(Jobs!$D$4:$D$503,MATCH($B36,Jobs!$W$4:$W$503,0)),"") | E36: =IFERROR(INDEX(Jobs!$E$4:$E$503,MATCH($B36,Jobs!$W$4:$W$503,0)),"") | G36: =IFERROR(INDEX(Jobs!$L$4:$L$503,MATCH($B36,Jobs!$W$4:$W$503,0)),"") | H36: =IFERROR(INDEX(Jobs!$R$4:$R$503,MATCH($B36,Jobs!$W$4:$W$503,0)),"") | I36: =IFERROR(INDEX(Jobs!$Q$4:$Q$503,MATCH($B36,Jobs!$W$4:$W$503,0)),"")
B37: 8 | C37: =IFERROR(INDEX(Jobs!$A$4:$A$503,MATCH($B37,Jobs!$W$4:$W$503,0)),"") | D37: =IFERROR(INDEX(Jobs!$D$4:$D$503,MATCH($B37,Jobs!$W$4:$W$503,0)),"") | E37: =IFERROR(INDEX(Jobs!$E$4:$E$503,MATCH($B37,Jobs!$W$4:$W$503,0)),"") | G37: =IFERROR(INDEX(Jobs!$L$4:$L$503,MATCH($B37,Jobs!$W$4:$W$503,0)),"") | H37: =IFERROR(INDEX(Jobs!$R$4:$R$503,MATCH($B37,Jobs!$W$4:$W$503,0)),"") | I37: =IFERROR(INDEX(Jobs!$Q$4:$Q$503,MATCH($B37,Jobs!$W$4:$W$503,0)),"")
B38: 9 | C38: =IFERROR(INDEX(Jobs!$A$4:$A$503,MATCH($B38,Jobs!$W$4:$W$503,0)),"") | D38: =IFERROR(INDEX(Jobs!$D$4:$D$503,MATCH($B38,Jobs!$W$4:$W$503,0)),"") | E38: =IFERROR(INDEX(Jobs!$E$4:$E$503,MATCH($B38,Jobs!$W$4:$W$503,0)),"") | G38: =IFERROR(INDEX(Jobs!$L$4:$L$503,MATCH($B38,Jobs!$W$4:$W$503,0)),"") | H38: =IFERROR(INDEX(Jobs!$R$4:$R$503,MATCH($B38,Jobs!$W$4:$W$503,0)),"") | I38: =IFERROR(INDEX(Jobs!$Q$4:$Q$503,MATCH($B38,Jobs!$W$4:$W$503,0)),"")
B39: 10 | C39: =IFERROR(INDEX(Jobs!$A$4:$A$503,MATCH($B39,Jobs!$W$4:$W$503,0)),"") | D39: =IFERROR(INDEX(Jobs!$D$4:$D$503,MATCH($B39,Jobs!$W$4:$W$503,0)),"") | E39: =IFERROR(INDEX(Jobs!$E$4:$E$503,MATCH($B39,Jobs!$W$4:$W$503,0)),"") | G39: =IFERROR(INDEX(Jobs!$L$4:$L$503,MATCH($B39,Jobs!$W$4:$W$503,0)),"") | H39: =IFERROR(INDEX(Jobs!$R$4:$R$503,MATCH($B39,Jobs!$W$4:$W$503,0)),"") | I39: =IFERROR(INDEX(Jobs!$Q$4:$Q$503,MATCH($B39,Jobs!$W$4:$W$503,0)),"")
B40: 11 | C40: =IFERROR(INDEX(Jobs!$A$4:$A$503,MATCH($B40,Jobs!$W$4:$W$503,0)),"") | D40: =IFERROR(INDEX(Jobs!$D$4:$D$503,MATCH($B40,Jobs!$W$4:$W$503,0)),"") | E40: =IFERROR(INDEX(Jobs!$E$4:$E$503,MATCH($B40,Jobs!$W$4:$W$503,0)),"") | G40: =IFERROR(INDEX(Jobs!$L$4:$L$503,MATCH($B40,Jobs!$W$4:$W$503,0)),"") | H40: =IFERROR(INDEX(Jobs!$R$4:$R$503,MATCH($B40,Jobs!$W$4:$W$503,0)),"") | I40: =IFERROR(INDEX(Jobs!$Q$4:$Q$503,MATCH($B40,Jobs!$W$4:$W$503,0)),"")
B41: 12 | C41: =IFERROR(INDEX(Jobs!$A$4:$A$503,MATCH($B41,Jobs!$W$4:$W$503,0)),"") | D41: =IFERROR(INDEX(Jobs!$D$4:$D$503,MATCH($B41,Jobs!$W$4:$W$503,0)),"") | E41: =IFERROR(INDEX(Jobs!$E$4:$E$503,MATCH($B41,Jobs!$W$4:$W$503,0)),"") | G41: =IFERROR(INDEX(Jobs!$L$4:$L$503,MATCH($B41,Jobs!$W$4:$W$503,0)),"") | H41: =IFERROR(INDEX(Jobs!$R$4:$R$503,MATCH($B41,Jobs!$W$4:$W$503,0)),"") | I41: =IFERROR(INDEX(Jobs!$Q$4:$Q$503,MATCH($B41,Jobs!$W$4:$W$503,0)),"")
... B44: 15 | C44: =IFERROR(INDEX(Jobs!$A$4:$A$503,MATCH($B44,Jobs!$W$4:$W$503,0)),"") | D44: =IFERROR(INDEX(Jobs!$D$4:$D$503,MATCH($B44,Jobs!$W$4:$W$503,0)),"") | E44: =IFERROR(INDEX(Jobs!$E$4:$E$503,MATCH($B44,Jobs!$W$4:$W$503,0)),"") | G44: =IFERROR(INDEX(Jobs!$L$4:$L$503,MATCH($B44,Jobs!$W$4:$W$503,0)),"") | H44: =IFERROR(INDEX(Jobs!$R$4:$R$503,MATCH($B44,Jobs!$W$4:$W$503,0)),"") | I44: =IFERROR(INDEX(Jobs!$Q$4:$Q$503,MATCH($B44,Jobs!$W$4:$W$503,0)),"")
B45: =IF(COUNT(Jobs!$W$4:$W$503)=0,"Nothing urgent - great job!",IF(MAX(Jobs!$W$4:$W$503)<=15,"All "&MAX(Jobs!$W$4:$W$503)&" urgent job(s) shown.","Showing the first 15 of "&MAX(Jobs!$W$4:$W$503)&" urgent jobs. Filter the Alert column on the Jobs sheet to see all.")) -> All 3 urgent job(s) shown.
B48: Jobs added by each user
B49: User | C49: Jobs added | D49: Applied | E49: Interviews
B50: =IF(Settings!K11="","",Settings!K11) -> Sample User | C50: =IF($B50="","",COUNTIF(Jobs!$C$4:$C$503,$B50)) -> 5 | D50: =IF($B50="","",COUNTIFS(Jobs!$C$4:$C$503,$B50,Jobs!$M$4:$M$503,">0")) -> 3 | E50: =IF($B50="","",COUNTIFS(Jobs!$C$4:$C$503,$B50,Jobs!$L$4:$L$503,"Interview")) -> 1
B51: =IF(Settings!K12="","",Settings!K12) | C51: =IF($B51="","",COUNTIF(Jobs!$C$4:$C$503,$B51)) | D51: =IF($B51="","",COUNTIFS(Jobs!$C$4:$C$503,$B51,Jobs!$M$4:$M$503,">0")) | E51: =IF($B51="","",COUNTIFS(Jobs!$C$4:$C$503,$B51,Jobs!$L$4:$L$503,"Interview"))
B52: =IF(Settings!K13="","",Settings!K13) | C52: =IF($B52="","",COUNTIF(Jobs!$C$4:$C$503,$B52)) | D52: =IF($B52="","",COUNTIFS(Jobs!$C$4:$C$503,$B52,Jobs!$M$4:$M$503,">0")) | E52: =IF($B52="","",COUNTIFS(Jobs!$C$4:$C$503,$B52,Jobs!$L$4:$L$503,"Interview"))
...

Sheet Jobs
A1: JOB TRACKER
A2: Blue headers = you type here | Grey headers = automatic (do not type) | Add each job on a new row. Status colours & alerts update by themselves.
A3: ID | B3: Date Added | C3: Added By | D3: Company | E3: Job Title | F3: Location | G3: Work Type | H3: Source | I3: Job Link | J3: Salary Range | K3: Priority | L3: Status | M3: Applied Date | N3: Deadline | O3: Last Follow-up | P3: Next Follow-up | Q3: Days to Action | R3: Alert | S3: Contact Name | T3: Contact Email | U3: Notes | V3: Last Reminder Sent | W3: Queue #
A4: =IF($D4="","","JOB-"&TEXT(ROW()-3,"000")) -> JOB-001 | B4: 46299 | C4: Sample User | D4: Acme Corp | E4: Data Analyst | F4: Karachi | G4: Hybrid | H4: LinkedIn | I4: https://example.com/job/1 | J4: $1,200/mo | K4: High | L4: To Apply | N4: 46304 | P4: =IF(OR($D4="",$M4=""),"",IF(IFERROR(INDEX(Settings!$C$11:$C$19,MATCH($L4,Settings!$B$11:$B$19,0)),"Yes")="No","",MAX($M4,$O4)+Settings!$C$6)) | Q4: =IF($D4="","",IF(IFERROR(INDEX(Settings!$C$11:$C$19,MATCH($L4,Settings!$B$11:$B$19,0)),"Yes")="No","",IF($M4="",IF($N4="","",$N4-TODAY()),IF($P4="","",$P4-TODAY())))) -> 2 | R4: =IF($D4="","",IF(IFERROR(INDEX(Settings!$C$11:$C$19,MATCH($L4,Settings!$B$11:$B$19,0)),"Yes")="No","CLOSED",IF($M4="",IF($N4="","ON TRACK",IF($N4<TODAY(),"OVERDUE",IF($N4-TODAY()<=Settings!$C$5,"DUE SOON","ON TRACK"))),IF($P4<=TODAY(),"FOLLOW-UP DUE","ON TRACK")))) -> DUE SOON | S4: Hiring Manager | T4: hr@acme.example | U4: SAMPLE ROW - delete me | W4: =IF(OR($R4="OVERDUE",$R4="DUE SOON",$R4="FOLLOW-UP DUE"),MAX(W$3:W3)+1,"") -> 1
A5: =IF($D5="","","JOB-"&TEXT(ROW()-3,"000")) -> JOB-002 | B5: 46296 | C5: Sample User | D5: Globex | E5: Backend Developer | F5: Remote | G5: Remote | H5: Indeed | I5: https://example.com/job/2 | J5: $2,000/mo | K5: High | L5: To Apply | N5: 46300 | P5: =IF(OR($D5="",$M5=""),"",IF(IFERROR(INDEX(Settings!$C$11:$C$19,MATCH($L5,Settings!$B$11:$B$19,0)),"Yes")="No","",MAX($M5,$O5)+Settings!$C$6)) | Q5: =IF($D5="","",IF(IFERROR(INDEX(Settings!$C$11:$C$19,MATCH($L5,Settings!$B$11:$B$19,0)),"Yes")="No","",IF($M5="",IF($N5="","",$N5-TODAY()),IF($P5="","",$P5-TODAY())))) -> -2 | R5: =IF($D5="","",IF(IFERROR(INDEX(Settings!$C$11:$C$19,MATCH($L5,Settings!$B$11:$B$19,0)),"Yes")="No","CLOSED",IF($M5="",IF($N5="","ON TRACK",IF($N5<TODAY(),"OVERDUE",IF($N5-TODAY()<=Settings!$C$5,"DUE SOON","ON TRACK"))),IF($P5<=TODAY(),"FOLLOW-UP DUE","ON TRACK")))) -> OVERDUE | U5: SAMPLE - deadline passed | W5: =IF(OR($R5="OVERDUE",$R5="DUE SOON",$R5="FOLLOW-UP DUE"),MAX(W$3:W4)+1,"") -> 2
A6: =IF($D6="","","JOB-"&TEXT(ROW()-3,"000")) -> JOB-003 | B6: 46290 | C6: Sample User | D6: Initech | E6: Python Developer | F6: Lahore | G6: On-site | H6: Referral | I6: https://example.com/job/3 | J6: $900/mo | K6: Medium | L6: Applied | M6: 46293 | P6: =IF(OR($D6="",$M6=""),"",IF(IFERROR(INDEX(Settings!$C$11:$C$19,MATCH($L6,Settings!$B$11:$B$19,0)),"Yes")="No","",MAX($M6,$O6)+Settings!$C$6)) -> 46300 | Q6: =IF($D6="","",IF(IFERROR(INDEX(Settings!$C$11:$C$19,MATCH($L6,Settings!$B$11:$B$19,0)),"Yes")="No","",IF($M6="",IF($N6="","",$N6-TODAY()),IF($P6="","",$P6-TODAY())))) -> -2 | R6: =IF($D6="","",IF(IFERROR(INDEX(Settings!$C$11:$C$19,MATCH($L6,Settings!$B$11:$B$19,0)),"Yes")="No","CLOSED",IF($M6="",IF($N6="","ON TRACK",IF($N6<TODAY(),"OVERDUE",IF($N6-TODAY()<=Settings!$C$5,"DUE SOON","ON TRACK"))),IF($P6<=TODAY(),"FOLLOW-UP DUE","ON TRACK")))) -> FOLLOW-UP DUE | S6: Ayesha Khan | T6: ayesha@initech.example | U6: SAMPLE - follow-up overdue | W6: =IF(OR($R6="OVERDUE",$R6="DUE SOON",$R6="FOLLOW-UP DUE"),MAX(W$3:W5)+1,"") -> 3
A7: =IF($D7="","","JOB-"&TEXT(ROW()-3,"000")) -> JOB-004 | B7: 46294 | C7: Sample User | D7: Umbrella Labs | E7: ML Engineer | F7: Remote | G7: Remote | H7: Company Site | I7: https://example.com/job/4 | J7: $2,500/mo | K7: High | L7: Interview | M7: 46296 | P7: =IF(OR($D7="",$M7=""),"",IF(IFERROR(INDEX(Settings!$C$11:$C$19,MATCH($L7,Settings!$B$11:$B$19,0)),"Yes")="No","",MAX($M7,$O7)+Settings!$C$6)) -> 46303 | Q7: =IF($D7="","",IF(IFERROR(INDEX(Settings!$C$11:$C$19,MATCH($L7,Settings!$B$11:$B$19,0)),"Yes")="No","",IF($M7="",IF($N7="","",$N7-TODAY()),IF($P7="","",$P7-TODAY())))) -> 1 | R7: =IF($D7="","",IF(IFERROR(INDEX(Settings!$C$11:$C$19,MATCH($L7,Settings!$B$11:$B$19,0)),"Yes")="No","CLOSED",IF($M7="",IF($N7="","ON TRACK",IF($N7<TODAY(),"OVERDUE",IF($N7-TODAY()<=Settings!$C$5,"DUE SOON","ON TRACK"))),IF($P7<=TODAY(),"FOLLOW-UP DUE","ON TRACK")))) -> ON TRACK | S7: Recruiter | T7: jobs@umbrella.example | U7: SAMPLE - interview stage | W7: =IF(OR($R7="OVERDUE",$R7="DUE SOON",$R7="FOLLOW-UP DUE"),MAX(W$3:W6)+1,"")
A8: =IF($D8="","","JOB-"&TEXT(ROW()-3,"000")) -> JOB-005 | B8: 46282 | C8: Sample User | D8: Hooli | E8: Frontend Developer | F8: Islamabad | G8: Hybrid | H8: Glassdoor | I8: https://example.com/job/5 | J8: $1,000/mo | K8: Low | L8: Rejected | M8: 46284 | P8: =IF(OR($D8="",$M8=""),"",IF(IFERROR(INDEX(Settings!$C$11:$C$19,MATCH($L8,Settings!$B$11:$B$19,0)),"Yes")="No","",MAX($M8,$O8)+Settings!$C$6)) | Q8: =IF($D8="","",IF(IFERROR(INDEX(Settings!$C$11:$C$19,MATCH($L8,Settings!$B$11:$B$19,0)),"Yes")="No","",IF($M8="",IF($N8="","",$N8-TODAY()),IF($P8="","",$P8-TODAY())))) | R8: =IF($D8="","",IF(IFERROR(INDEX(Settings!$C$11:$C$19,MATCH($L8,Settings!$B$11:$B$19,0)),"Yes")="No","CLOSED",IF($M8="",IF($N8="","ON TRACK",IF($N8<TODAY(),"OVERDUE",IF($N8-TODAY()<=Settings!$C$5,"DUE SOON","ON TRACK"))),IF($P8<=TODAY(),"FOLLOW-UP DUE","ON TRACK")))) -> CLOSED | U8: SAMPLE - closed | W8: =IF(OR($R8="OVERDUE",$R8="DUE SOON",$R8="FOLLOW-UP DUE"),MAX(W$3:W7)+1,"")
A9: =IF($D9="","","JOB-"&TEXT(ROW()-3,"000")) | P9: =IF(OR($D9="",$M9=""),"",IF(IFERROR(INDEX(Settings!$C$11:$C$19,MATCH($L9,Settings!$B$11:$B$19,0)),"Yes")="No","",MAX($M9,$O9)+Settings!$C$6)) | Q9: =IF($D9="","",IF(IFERROR(INDEX(Settings!$C$11:$C$19,MATCH($L9,Settings!$B$11:$B$19,0)),"Yes")="No","",IF($M9="",IF($N9="","",$N9-TODAY()),IF($P9="","",$P9-TODAY())))) | R9: =IF($D9="","",IF(IFERROR(INDEX(Settings!$C$11:$C$19,MATCH($L9,Settings!$B$11:$B$19,0)),"Yes")="No","CLOSED",IF($M9="",IF($N9="","ON TRACK",IF($N9<TODAY(),"OVERDUE",IF($N9-TODAY()<=Settings!$C$5,"DUE SOON","ON TRACK"))),IF($P9<=TODAY(),"FOLLOW-UP DUE","ON TRACK")))) | W9: =IF(OR($R9="OVERDUE",$R9="DUE SOON",$R9="FOLLOW-UP DUE"),MAX(W$3:W8)+1,"")
A10: =IF($D10="","","JOB-"&TEXT(ROW()-3,"000")) | P10: =IF(OR($D10="",$M10=""),"",IF(IFERROR(INDEX(Settings!$C$11:$C$19,MATCH($L10,Settings!$B$11:$B$19,0)),"Yes")="No","",MAX($M10,$O10)+Settings!$C$6)) | Q10: =IF($D10="","",IF(IFERROR(INDEX(Settings!$C$11:$C$19,MATCH($L10,Settings!$B$11:$B$19,0)),"Yes")="No","",IF($M10="",IF($N10="","",$N10-TODAY()),IF($P10="","",$P10-TODAY())))) | R10: =IF($D10="","",IF(IFERROR(INDEX(Settings!$C$11:$C$19,MATCH($L10,Settings!$B$11:$B$19,0)),"Yes")="No","CLOSED",IF($M10="",IF($N10="","ON TRACK",IF($N10<TODAY(),"OVERDUE",IF($N10-TODAY()<=Settings!$C$5,"DUE SOON","ON TRACK"))),IF($P10<=TODAY(),"FOLLOW-UP DUE","ON TRACK")))) | W10: =IF(OR($R10="OVERDUE",$R10="DUE SOON",$R10="FOLLOW-UP DUE"),MAX(W$3:W9)+1,"")
A11: =IF($D11="","","JOB-"&TEXT(ROW()-3,"000")) | P11: =IF(OR($D11="",$M11=""),"",IF(IFERROR(INDEX(Settings!$C$11:$C$19,MATCH($L11,Settings!$B$11:$B$19,0)),"Yes")="No","",MAX($M11,$O11)+Settings!$C$6)) | Q11: =IF($D11="","",IF(IFERROR(INDEX(Settings!$C$11:$C$19,MATCH($L11,Settings!$B$11:$B$19,0)),"Yes")="No","",IF($M11="",IF($N11="","",$N11-TODAY()),IF($P11="","",$P11-TODAY())))) | R11: =IF($D11="","",IF(IFERROR(INDEX(Settings!$C$11:$C$19,MATCH($L11,Settings!$B$11:$B$19,0)),"Yes")="No","CLOSED",IF($M11="",IF($N11="","ON TRACK",IF($N11<TODAY(),"OVERDUE",IF($N11-TODAY()<=Settings!$C$5,"DUE SOON","ON TRACK"))),IF($P11<=TODAY(),"FOLLOW-UP DUE","ON TRACK")))) | W11: =IF(OR($R11="OVERDUE",$R11="DUE SOON",$R11="FOLLOW-UP DUE"),MAX(W$3:W10)+1,"")
A12: =IF($D12="","","JOB-"&TEXT(ROW()-3,"000")) | P12: =IF(OR($D12="",$M12=""),"",IF(IFERROR(INDEX(Settings!$C$11:$C$19,MATCH($L12,Settings!$B$11:$B$19,0)),"Yes")="No","",MAX($M12,$O12)+Settings!$C$6)) | Q12: =IF($D12="","",IF(IFERROR(INDEX(Settings!$C$11:$C$19,MATCH($L12,Settings!$B$11:$B$19,0)),"Yes")="No","",IF($M12="",IF($N12="","",$N12-TODAY()),IF($P12="","",$P12-TODAY())))) | R12: =IF($D12="","",IF(IFERROR(INDEX(Settings!$C$11:$C$19,MATCH($L12,Settings!$B$11:$B$19,0)),"Yes")="No","CLOSED",IF($M12="",IF($N12="","ON TRACK",IF($N12<TODAY(),"OVERDUE",IF($N12-TODAY()<=Settings!$C$5,"DUE SOON","ON TRACK"))),IF($P12<=TODAY(),"FOLLOW-UP DUE","ON TRACK")))) | W12: =IF(OR($R12="OVERDUE",$R12="DUE SOON",$R12="FOLLOW-UP DUE"),MAX(W$3:W11)+1,"")
A13: =IF($D13="","","JOB-"&TEXT(ROW()-3,"000")) | P13: =IF(OR($D13="",$M13=""),"",IF(IFERROR(INDEX(Settings!$C$11:$C$19,MATCH($L13,Settings!$B$11:$B$19,0)),"Yes")="No","",MAX($M13,$O13)+Settings!$C$6)) | Q13: =IF($D13="","",IF(IFERROR(INDEX(Settings!$C$11:$C$19,MATCH($L13,Settings!$B$11:$B$19,0)),"Yes")="No","",IF($M13="",IF($N13="","",$N13-TODAY()),IF($P13="","",$P13-TODAY())))) | R13: =IF($D13="","",IF(IFERROR(INDEX(Settings!$C$11:$C$19,MATCH($L13,Settings!$B$11:$B$19,0)),"Yes")="No","CLOSED",IF($M13="",IF($N13="","ON TRACK",IF($N13<TODAY(),"OVERDUE",IF($N13-TODAY()<=Settings!$C$5,"DUE SOON","ON TRACK"))),IF($P13<=TODAY(),"FOLLOW-UP DUE","ON TRACK")))) | W13: =IF(OR($R13="OVERDUE",$R13="DUE SOON",$R13="FOLLOW-UP DUE"),MAX(W$3:W12)+1,"")
A14: =IF($D14="","","JOB-"&TEXT(ROW()-3,"000")) | P14: =IF(OR($D14="",$M14=""),"",IF(IFERROR(INDEX(Settings!$C$11:$C$19,MATCH($L14,Settings!$B$11:$B$19,0)),"Yes")="No","",MAX($M14,$O14)+Settings!$C$6)) | Q14: =IF($D14="","",IF(IFERROR(INDEX(Settings!$C$11:$C$19,MATCH($L14,Settings!$B$11:$B$19,0)),"Yes")="No","",IF($M14="",IF($N14="","",$N14-TODAY()),IF($P14="","",$P14-TODAY())))) | R14: =IF($D14="","",IF(IFERROR(INDEX(Settings!$C$11:$C$19,MATCH($L14,Settings!$B$11:$B$19,0)),"Yes")="No","CLOSED",IF($M14="",IF($N14="","ON TRACK",IF($N14<TODAY(),"OVERDUE",IF($N14-TODAY()<=Settings!$C$5,"DUE SOON","ON TRACK"))),IF($P14<=TODAY(),"FOLLOW-UP DUE","ON TRACK")))) | W14: =IF(OR($R14="OVERDUE",$R14="DUE SOON",$R14="FOLLOW-UP DUE"),MAX(W$3:W13)+1,"")
A15: =IF($D15="","","JOB-"&TEXT(ROW()-3,"000")) | P15: =IF(OR($D15="",$M15=""),"",IF(IFERROR(INDEX(Settings!$C$11:$C$19,MATCH($L15,Settings!$B$11:$B$19,0)),"Yes")="No","",MAX($M15,$O15)+Settings!$C$6)) | Q15: =IF($D15="","",IF(IFERROR(INDEX(Settings!$C$11:$C$19,MATCH($L15,Settings!$B$11:$B$19,0)),"Yes")="No","",IF($M15="",IF($N15="","",$N15-TODAY()),IF($P15="","",$P15-TODAY())))) | R15: =IF($D15="","",IF(IFERROR(INDEX(Settings!$C$11:$C$19,MATCH($L15,Settings!$B$11:$B$19,0)),"Yes")="No","CLOSED",IF($M15="",IF($N15="","ON TRACK",IF($N15<TODAY(),"OVERDUE",IF($N15-TODAY()<=Settings!$C$5,"DUE SOON","ON TRACK"))),IF($P15<=TODAY(),"FOLLOW-UP DUE","ON TRACK")))) | W15: =IF(OR($R15="OVERDUE",$R15="DUE SOON",$R15="FOLLOW-UP DUE"),MAX(W$3:W14)+1,"")
A16: =IF($D16="","","JOB-"&TEXT(ROW()-3,"000")) | P16: =IF(OR($D16="",$M16=""),"",IF(IFERROR(INDEX(Settings!$C$11:$C$19,MATCH($L16,Settings!$B$11:$B$19,0)),"Yes")="No","",MAX($M16,$O16)+Settings!$C$6)) | Q16: =IF($D16="","",IF(IFERROR(INDEX(Settings!$C$11:$C$19,MATCH($L16,Settings!$B$11:$B$19,0)),"Yes")="No","",IF($M16="",IF($N16="","",$N16-TODAY()),IF($P16="","",$P16-TODAY())))) | R16: =IF($D16="","",IF(IFERROR(INDEX(Settings!$C$11:$C$19,MATCH($L16,Settings!$B$11:$B$19,0)),"Yes")="No","CLOSED",IF($M16="",IF($N16="","ON TRACK",IF($N16<TODAY(),"OVERDUE",IF($N16-TODAY()<=Settings!$C$5,"DUE SOON","ON TRACK"))),IF($P16<=TODAY(),"FOLLOW-UP DUE","ON TRACK")))) | W16: =IF(OR($R16="OVERDUE",$R16="DUE SOON",$R16="FOLLOW-UP DUE"),MAX(W$3:W15)+1,"")
A17: =IF($D17="","","JOB-"&TEXT(ROW()-3,"000")) | P17: =IF(OR($D17="",$M17=""),"",IF(IFERROR(INDEX(Settings!$C$11:$C$19,MATCH($L17,Settings!$B$11:$B$19,0)),"Yes")="No","",MAX($M17,$O17)+Settings!$C$6)) | Q17: =IF($D17="","",IF(IFERROR(INDEX(Settings!$C$11:$C$19,MATCH($L17,Settings!$B$11:$B$19,0)),"Yes")="No","",IF($M17="",IF($N17="","",$N17-TODAY()),IF($P17="","",$P17-TODAY())))) | R17: =IF($D17="","",IF(IFERROR(INDEX(Settings!$C$11:$C$19,MATCH($L17,Settings!$B$11:$B$19,0)),"Yes")="No","CLOSED",IF($M17="",IF($N17="","ON TRACK",IF($N17<TODAY(),"OVERDUE",IF($N17-TODAY()<=Settings!$C$5,"DUE SOON","ON TRACK"))),IF($P17<=TODAY(),"FOLLOW-UP DUE","ON TRACK")))) | W17: =IF(OR($R17="OVERDUE",$R17="DUE SOON",$R17="FOLLOW-UP DUE"),MAX(W$3:W16)+1,"")
A18: =IF($D18="","","JOB-"&TEXT(ROW()-3,"000")) | P18: =IF(OR($D18="",$M18=""),"",IF(IFERROR(INDEX(Settings!$C$11:$C$19,MATCH($L18,Settings!$B$11:$B$19,0)),"Yes")="No","",MAX($M18,$O18)+Settings!$C$6)) | Q18: =IF($D18="","",IF(IFERROR(INDEX(Settings!$C$11:$C$19,MATCH($L18,Settings!$B$11:$B$19,0)),"Yes")="No","",IF($M18="",IF($N18="","",$N18-TODAY()),IF($P18="","",$P18-TODAY())))) | R18: =IF($D18="","",IF(IFERROR(INDEX(Settings!$C$11:$C$19,MATCH($L18,Settings!$B$11:$B$19,0)),"Yes")="No","CLOSED",IF($M18="",IF($N18="","ON TRACK",IF($N18<TODAY(),"OVERDUE",IF($N18-TODAY()<=Settings!$C$5,"DUE SOON","ON TRACK"))),IF($P18<=TODAY(),"FOLLOW-UP DUE","ON TRACK")))) | W18: =IF(OR($R18="OVERDUE",$R18="DUE SOON",$R18="FOLLOW-UP DUE"),MAX(W$3:W17)+1,"")
A19: =IF($D19="","","JOB-"&TEXT(ROW()-3,"000")) | P19: =IF(OR($D19="",$M19=""),"",IF(IFERROR(INDEX(Settings!$C$11:$C$19,MATCH($L19,Settings!$B$11:$B$19,0)),"Yes")="No","",MAX($M19,$O19)+Settings!$C$6)) | Q19: =IF($D19="","",IF(IFERROR(INDEX(Settings!$C$11:$C$19,MATCH($L19,Settings!$B$11:$B$19,0)),"Yes")="No","",IF($M19="",IF($N19="","",$N19-TODAY()),IF($P19="","",$P19-TODAY())))) | R19: =IF($D19="","",IF(IFERROR(INDEX(Settings!$C$11:$C$19,MATCH($L19,Settings!$B$11:$B$19,0)),"Yes")="No","CLOSED",IF($M19="",IF($N19="","ON TRACK",IF($N19<TODAY(),"OVERDUE",IF($N19-TODAY()<=Settings!$C$5,"DUE SOON","ON TRACK"))),IF($P19<=TODAY(),"FOLLOW-UP DUE","ON TRACK")))) | W19: =IF(OR($R19="OVERDUE",$R19="DUE SOON",$R19="FOLLOW-UP DUE"),MAX(W$3:W18)+1,"")
A20: =IF($D20="","","JOB-"&TEXT(ROW()-3,"000")) | P20: =IF(OR($D20="",$M20=""),"",IF(IFERROR(INDEX(Settings!$C$11:$C$19,MATCH($L20,Settings!$B$11:$B$19,0)),"Yes")="No","",MAX($M20,$O20)+Settings!$C$6)) | Q20: =IF($D20="","",IF(IFERROR(INDEX(Settings!$C$11:$C$19,MATCH($L20,Settings!$B$11:$B$19,0)),"Yes")="No","",IF($M20="",IF($N20="","",$N20-TODAY()),IF($P20="","",$P20-TODAY())))) | R20: =IF($D20="","",IF(IFERROR(INDEX(Settings!$C$11:$C$19,MATCH($L20,Settings!$B$11:$B$19,0)),"Yes")="No","CLOSED",IF($M20="",IF($N20="","ON TRACK",IF($N20<TODAY(),"OVERDUE",IF($N20-TODAY()<=Settings!$C$5,"DUE SOON","ON TRACK"))),IF($P20<=TODAY(),"FOLLOW-UP DUE","ON TRACK")))) | W20: =IF(OR($R20="OVERDUE",$R20="DUE SOON",$R20="FOLLOW-UP DUE"),MAX(W$3:W19)+1,"")
... A503: =IF($D503="","","JOB-"&TEXT(ROW()-3,"000")) | P503: =IF(OR($D503="",$M503=""),"",IF(IFERROR(INDEX(Settings!$C$11:$C$19,MATCH($L503,Settings!$B$11:$B$19,0)),"Yes")="No","",MAX($M503,$O503)+Settings!$C$6)) | Q503: =IF($D503="","",IF(IFERROR(INDEX(Settings!$C$11:$C$19,MATCH($L503,Settings!$B$11:$B$19,0)),"Yes")="No","",IF($M503="",IF($N503="","",$N503-TODAY()),IF($P503="","",$P503-TODAY())))) | R503: =IF($D503="","",IF(IFERROR(INDEX(Settings!$C$11:$C$19,MATCH($L503,Settings!$B$11:$B$19,0)),"Yes")="No","CLOSED",IF($M503="",IF($N503="","ON TRACK",IF($N503<TODAY(),"OVERDUE",IF($N503-TODAY()<=Settings!$C$5,"DUE SOON","ON TRACK"))),IF($P503<=TODAY(),"FOLLOW-UP DUE","ON TRACK")))) | W503: =IF(OR($R503="OVERDUE",$R503="DUE SOON",$R503="FOLLOW-UP DUE"),MAX(W$3:W502)+1,"")

Sheet Reminder Log
A1: Time sent | B1: Sent to | C1: Jobs in email | D1: Job IDs
A2: (The reminder script writes a row here every time it sends an email.)

Sheet Settings
B1: Settings
B2: Blue cells = you can change them. Everything else updates automatically.
B4: Reminder email (owner gets every alert) | C4: your-email@gmail.com | D4: Replace with your own email. Assumption: placeholder value.
B5: Warn before deadline (days) | C5: 3 | D5: Job is 'DUE SOON' when deadline is within this many days.
B6: Follow up after applying (days) | C6: 7 | D6: Next follow-up = last action date + this many days.
B7: Repeat reminder every (days) | C7: 2 | D7: Script will not email the same job again before this gap.
B10: Status | C10: Counts as open? | E10: Priority | G10: Work Type | I10: Source | K10: Users (Added By)
B11: Wishlist | C11: Yes | E11: High | G11: Remote | I11: LinkedIn | K11: Sample User
B12: To Apply | C12: Yes | E12: Medium | G12: Hybrid | I12: Indeed
B13: Applied | C13: Yes | E13: Low | G13: On-site | I13: Company Site
B14: Interview | C14: Yes | I14: Referral
B15: Offer | C15: Yes | I15: Rozee.pk
B16: Accepted | C16: No | I16: Glassdoor
B17: Rejected | C17: No | I17: Other
B18: Withdrawn | C18: No
B19: Ghosted | C19: No
B21: 'Open' = job still needs your attention. 'No' rows are CLOSED and never trigger reminders.

Sheet How To Use
B2: HOW TO USE THIS JOB TRACKER
B3: 1. Add a job: go to the Jobs sheet, type on the next empty row (Company, Job Title, Status, Deadline...). Or use menu: Job Tracker > Add Job (Google Sheets).
B4: 2. Not applied yet? Set Status = To Apply and fill Deadline. You get DUE SOON / OVERDUE alerts.
B5: 3. Applied? Fill Applied Date and Status = Applied. Next Follow-up date appears automatically (Applied Date + 7 days, change in Settings).
B6: 4. After you send a follow-up, put today's date in Last Follow-up (or menu: Job Tracker > Mark Follow-up Done). The next follow-up date moves forward.
B7: 5. Job finished (Rejected / Withdrawn / Accepted / Ghosted)? Change Status. It becomes CLOSED and reminders stop.
B8: 6. Many users: share the Google Sheet (Editor access). Everyone adds jobs in the same sheet. 'Added By' fills automatically.
B10: AUTOMATIC EMAIL REMINDERS (one-time 3-minute setup)
B11: a) Upload Job-Tracker.xlsx to Google Drive > open with Google Sheets > File > Save as Google Sheets.
B12: b) Extensions > Apps Script > delete any code > paste everything from Code.gs > Save.
B13: c) Fill your email in Settings sheet (C4).
B14: d) Reload the sheet. Menu 'Job Tracker' appears > click 'Turn On Daily Auto-Reminders' > allow permissions.
... B19: Sample rows (notes say SAMPLE) are examples - delete them before real use.
